Workbook

Sheet Бенчмарк
B1: Дебаг-тесты на разных устройствах. Тест ведётся на одних и тех же бахах данных | C1: 51546 записей
D5: 1. ТЕСТИРОВАНИЕ ПО ЗАГРУЗКЕ И НОРМАЛИЗАЦИИ | L5: 2. Поиск - параметры: (Любой - 300 - 2000 - y) - по 799 записям
B6: Устройство | C6: ЦП + Тип памяти | D6: ОЗУ (ГБ) | E6: Тестирование | F6: Загрузка записей (мс) | G6: Нормализация (мс) | H6: Индексы построены (мс) | I6: Итого выполнение (мс) | J6: Память ИТОГО (КБ) | K6: Выполнения в среднем (мкс) | L6: Линейный (мкс) | M6: Индексный (мкс) | N6: Линейный - средний (мкс) | O6: Индексный - средний (мкс) | Q6: Ускорение T_linear/T_index
A7: 1 | B7: Устройство 1 (Laptop) | C7: 12th Gen Intel(R) Core(TM) i5-12450H | D7: 16 | E7: 1 | F7: 48 | G7: 65 | H7: 16 | I7: =SUM(F7:H7) -> 129 | J7: 13692 | K7: =(SUM(I7:I11)/COUNT(I7:I11))*1000 -> 129200 | L7: 3080 | M7: 525 | N7: =ROUND(AVERAGE(L7:L11),0) -> 2477 | O7: =ROUND(AVERAGE(M7:M11),0) -> 495 | Q7: =ROUND(N7/O7,1) -> 5
E8: 2 | F8: 45 | G8: 61 | H8: 21 | I8: =SUM(F8:H8) -> 127 | J8: 13692 | L8: 2872 | M8: 642
E9: 3 | F9: 46 | G9: 60 | H9: 17 | I9: =SUM(F9:H9) -> 123 | J9: 13692 | L9: 1609 | M9: 337
E10: 4 | F10: 54 | G10: 61 | H10: 17 | I10: =SUM(F10:H10) -> 132 | J10: 13692 | L10: 3157 | M10: 634
E11: 5 | F11: 52 | G11: 65 | H11: 18 | I11: =SUM(F11:H11) -> 135 | J11: 13692 | L11: 1666 | M11: 338
A12: 2 | B12: устройство 2 (Desktop) | C12: AMD FX(tm)-8300 Eight-Core Processor | D12: 8 | E12: 1 | F12: 259 | G12: 303 | H12: 83 | I12: =SUM(F12:H12) -> 645 | J12: 13692 | K12: =(SUM(I12:I16)/COUNT(I12:I16))*1000 -> 633800 | L12: 2198 | M12: 454 | N12: =ROUND(AVERAGE(L12:L16),0) -> 2531 | O12: =ROUND(AVERAGE(M12:M16),0) -> 534 | Q12: =ROUND(N12/O12,1) -> 4.7
E13: 2 | F13: 245 | G13: 290 | H13: 95 | I13: =SUM(F13:H13) -> 630 | J13: 13692 | L13: 2191 | M13: 444
E14: 3 | F14: 248 | G14: 291 | H14: 91 | I14: =SUM(F14:H14) -> 630 | J14: 13692 | L14: 3033 | M14: 638
E15: 4 | F15: 248 | G15: 295 | H15: 96 | I15: =SUM(F15:H15) -> 639 | J15: 13692 | L15: 3019 | M15: 718
E16: 5 | F16: 249 | G16: 289 | H16: 87 | I16: =SUM(F16:H16) -> 625 | J16: 13692 | L16: 2214 | M16: 417
A17: 3 | B17: устройство 3 (Desktop) | C17: AMD Ryzen 5 3500X 6-Core Processor | D17: 32 | E17: 1 | F17: 144 | G17: 169 | H17: 44 | I17: =SUM(F17:H17) -> 357 | J17: 13692 | K17: =(SUM(I17:I21)/COUNT(I17:I21))*1000 -> 352000 | L17: 1336 | M17: 470 | N17: =ROUND(AVERAGE(L17:L21),0) -> 1117 | O17: =ROUND(AVERAGE(M17:M21),0) -> 352 | Q17: =ROUND(N17/O17,1) -> 3.2
E18: 2 | F18: 136 | G18: 168 | H18: 46 | I18: =SUM(F18:H18) -> 350 | J18: 13692 | L18: 1032 | M18: 246
E19: 3 | F19: 138 | G19: 167 | H19: 47 | I19: =SUM(F19:H19) -> 352 | J19: 13692 | L19: 1168 | M19: 284
E20: 4 | F20: 137 | G20: 170 | H20: 42 | I20: =SUM(F20:H20) -> 349 | J20: 13692 | L20: 1062 | M20: 398
E21: 5 | F21: 139 | G21: 167 | H21: 46 | I21: =SUM(F21:H21) -> 352 | J21: 13692 | L21: 989 | M21: 362
A22: 4 | B22: устройство 4 (Laptop) | C22: AMD Ryzen 7 5800H with Radeon Graphics | D22: 32 | E22: 1 | F22: 104 | G22: 128 | H22: 43 | I22: =SUM(F22:H22) -> 275 | J22: 13692 | K22: =(SUM(I22:I26)/COUNT(I22:I26))*1000 -> 275400 | L22: 1190 | M22: 370 | N22: =ROUND(AVERAGE(L22:L26),0) -> 1207 | O22: =ROUND(AVERAGE(M22:M26),0) -> 355 | Q22: =ROUND(N22/O22,1) -> 3.4 | S22: СРЕДНЕЕ ГЕОМ УСКОРЕНИЕ
E23: 2 | F23: 106 | G23: 133 | H23: 43 | I23: =SUM(F23:H23) -> 282 | J23: 13692 | L23: 1282 | M23: 378
E24: 3 | F24: 103 | G24: 129 | H24: 43 | I24: =SUM(F24:H24) -> 275 | J24: 13692 | L24: 1136 | M24: 336
E25: 4 | F25: 104 | G25: 127 | H25: 42 | I25: =SUM(F25:H25) -> 273 | J25: 13692 | L25: 1283 | M25: 348
E26: 5 | F26: 104 | G26: 126 | H26: 42 | I26: =SUM(F26:H26) -> 272 | J26: 13692 | L26: 1144 | M26: 344
A27: 5 | B27: устройство 5 (Server) | C27: 13th Gen Intel(R) Core(TM) i5-13400 | D27: 32 | E27: 1 | F27: 77 | G27: 103 | H27: 25 | I27: =SUM(F27:H27) -> 205 | J27: 13692 | K27: =(SUM(I27:I31)/COUNT(I27:I31))*1000 -> 207200 | L27: 1207 | M27: 211 | N27: =ROUND(AVERAGE(L27:L31),0) -> 1063 | O27: =ROUND(AVERAGE(M27:M31),0) -> 248 | Q27: =ROUND(N27/O27,1) -> 4.3 | S27: =ROUND(GEOMEAN(Q7:Q51),2) -> 3.91 | U27: В среднем по гетерогенной группе устройств алгоритм дает ускорение в 3,91 раз
E28: 2 | F28: 77 | G28: 101 | H28: 29 | I28: =SUM(F28:H28) -> 207 | J28: 13692 | L28: 921 | M28: 250
E29: 3 | F29: 77 | G29: 101 | H29: 29 | I29: =SUM(F29:H29) -> 207 | J29: 13692 | L29: 955 | M29: 234
E30: 4 | F30: 77 | G30: 103 | H30: 30 | I30: =SUM(F30:H30) -> 210 | J30: 13692 | L30: 1254 | M30: 299
E31: 5 | F31: 77 | G31: 101 | H31: 29 | I31: =SUM(F31:H31) -> 207 | J31: 13692 | L31: 976 | M31: 245
A32: 6 | B32: устройство 6 (Tablet) | C32: Samsung Exynos 1380, 8-ядерный, 2.4 ГГц, 5 нм, Android 16 | D32: 12 | E32: 1 | F32: 713 | G32: 428 | H32: 130 | I32: =SUM(F32:H32) -> 1271 | J32: 12081 | K32: =(SUM(I32:I36)/COUNT(I32:I36))*1000 -> 1273200 | L32: 3154 | M32: 1338 | N32: =ROUND(AVERAGE(L32:L36),0) -> 3988 | O32: =ROUND(AVERAGE(M32:M36),0) -> 1516 | Q32: =ROUND(N32/O32,1) -> 2.6
E33: 2 | F33: 705 | G33: 425 | H33: 141 | I33: =SUM(F33:H33) -> 1271 | J33: 12081 | L33: 4174 | M33: 1619
E34: 3 | F34: 705 | G34: 426 | H34: 149 | I34: =SUM(F34:H34) -> 1280 | J34: 12081 | L34: 4145 | M34: 1509
E35: 4 | F35: 706 | G35: 425 | H35: 141 | I35: =SUM(F35:H35) -> 1272 | J35: 12081 | L35: 4265 | M35: 1508
E36: 5 | F36: 704 | G36: 425 | H36: 143 | I36: =SUM(F36:H36) -> 1272 | J36: 12081 | L36: 4203 | M36: 1608
A37: 7 | B37: устройство 7 (Phone) | C37: Qualcomm Snapdragon 870 Octa-Core, Android 14 | D37: 8 | E37: 1 | F37: 658 | G37: 388 | H37: 99 | I37: =SUM(F37:H37) -> 1145 | J37: 12081 | K37: =(SUM(I37:I41)/COUNT(I37:I41))*1000 -> 1124000 | L37: 7210 | M37: 2587 | N37: =ROUND(AVERAGE(L37:L41),0) -> 7597 | O37: =ROUND(AVERAGE(M37:M41),0) -> 2521 | Q37: =ROUND(N37/O37,1) -> 3
E38: 2 | F38: 617 | G38: 387 | H38: 111 | I38: =SUM(F38:H38) -> 1115 | J38: 12081 | L38: 13151 | M38: 3164
E39: 3 | F39: 619 | G39: 386 | H39: 110 | I39: =SUM(F39:H39) -> 1115 | J39: 12081 | L39: 7273 | M39: 2765
E40: 4 | F40: 624 | G40: 386 | H40: 116 | I40: =SUM(F40:H40) -> 1126 | J40: 12081 | L40: 2925 | M40: 1076
E41: 5 | F41: 624 | G41: 386 | H41: 109 | I41: =SUM(F41:H41) -> 1119 | J41: 12081 | L41: 7424 | M41: 3012
A42: 8 | B42: устройство 8 (Laptop) | C42: Intel Core Ultra 7 | D42: 32 | E42: 1 | F42: 128 | G42: 164 | H42: 44 | I42: =SUM(F42:H42) -> 336 | J42: 13692 | K42: =(SUM(I42:I46)/COUNT(I42:I46))*1000 -> 348600 | L42: 2264 | M42: 799 | N42: =ROUND(AVERAGE(L42:L46),0) -> 1780 | O42: =ROUND(AVERAGE(M42:M46),0) -> 553 | Q42: =ROUND(N42/O42,1) -> 3.2
E43: 2 | F43: 135 | G43: 187 | H43: 44 | I43: =SUM(F43:H43) -> 366 | J43: 13692 | L43: 1594 | M43: 479
...

Sheet Статистика Анализ
A1: ID | B1: Устройство | C1: Процессор | D1: Микроархитектура | E1: L3 Кэш (МБ) | F1: ОЗУ (ГБ) | G1: ОЗУ Тип | H1: Линейный (мкс) | I1: Индексный (мкс) | J1: Ускорение | K1: Время загрузки (мс)
A2: ="D" & ROW(A1) -> D1 | B2: ='Бенчмарк'!B56 -> Устройство 1 (Laptop) x86-64 | C2: ='Бенчмарк'!C56 -> 12th Gen Intel(R) Core(TM) i5-12450H x86-64 | D2: x86-64 | E2: 12 | F2: ='Бенчмарк'!D56 -> 16 | G2: DDR4 | H2: ='Бенчмарк'!E56 -> 2477 | I2: ='Бенчмарк'!F56 -> 495 | J2: ='Бенчмарк'!G56 -> 5 | K2: ='Бенчмарк'!H56 -> 129200
A3: ="D" & ROW(A2) -> D2 | B3: ='Бенчмарк'!B57 -> устройство 2 (Desktop) x86-64 | C3: ='Бенчмарк'!C57 -> AMD FX(tm)-8300 Eight-Core Processor x86-64 | D3: x86-64 | E3: 8 | F3: ='Бенчмарк'!D57 -> 8 | G3: DDR3 | H3: ='Бенчмарк'!E57 -> 2531 | I3: ='Бенчмарк'!F57 -> 534 | J3: ='Бенчмарк'!G57 -> 4.7 | K3: ='Бенчмарк'!H57 -> 633800
A4: ="D" & ROW(A3) -> D3 | B4: ='Бенчмарк'!B58 -> устройство 3 (Desktop) x86-64 | C4: ='Бенчмарк'!C58 -> AMD Ryzen 5 3500X 6-Core Processor x86-64 | D4: x86-64 | E4: 32 | F4: ='Бенчмарк'!D58 -> 32 | G4: DDR4 | H4: ='Бенчмарк'!E58 -> 1117 | I4: ='Бенчмарк'!F58 -> 352 | J4: ='Бенчмарк'!G58 -> 3.2 | K4: ='Бенчмарк'!H58 -> 352000
A5: ="D" & ROW(A4) -> D4 | B5: ='Бенчмарк'!B59 -> устройство 4 (Laptop) x86-64 | C5: ='Бенчмарк'!C59 -> AMD Ryzen 7 5800H with Radeon Graphics x86-64 | D5: x86-64 | E5: 16 | F5: ='Бенчмарк'!D59 -> 32 | G5: DDR4 | H5: ='Бенчмарк'!E59 -> 1207 | I5: ='Бенчмарк'!F59 -> 355 | J5: ='Бенчмарк'!G59 -> 3.4 | K5: ='Бенчмарк'!H59 -> 275400
A6: ="D" & ROW(A5) -> D5 | B6: ='Бенчмарк'!B60 -> устройство 5 (Server) x86-64 | C6: ='Бенчмарк'!C60 -> 13th Gen Intel(R) Core(TM) i5-13400 x86-64 | D6: x86-64 | E6: 20 | F6: ='Бенчмарк'!D60 -> 32 | G6: DDR5 | H6: ='Бенчмарк'!E60 -> 1063 | I6: ='Бенчмарк'!F60 -> 248 | J6: ='Бенчмарк'!G60 -> 4.3 | K6: ='Бенчмарк'!H60 -> 207200
A7: ="D" & ROW(A6) -> D6 | B7: ='Бенчмарк'!B61 -> устройство 6 (Tablet) ARMv8.2‑A | C7: ='Бенчмарк'!C61 -> Samsung Exynos 1380, 8-ядерный, 2.4 ГГц, 5 нм, Android 16 ARMv8.2‑A | D7: ARMv8.2‑A | E7: 0 | F7: ='Бенчмарк'!D61 -> 12 | G7: LPDDR | H7: ='Бенчмарк'!E61 -> 3988 | I7: ='Бенчмарк'!F61 -> 1516 | J7: ='Бенчмарк'!G61 -> 2.6 | K7: ='Бенчмарк'!H61 -> 1273200
A8: ="D" & ROW(A7) -> D7 | B8: ='Бенчмарк'!B62 -> устройство 7 (Phone) ARMv8.2‑A | C8: ='Бенчмарк'!C62 -> Qualcomm Snapdragon 870 Octa-Core, Android 14 ARMv8.2‑A | D8: ARMv8.2‑A | E8: 4 | F8: ='Бенчмарк'!D62 -> 8 | G8: LPDDR | H8: ='Бенчмарк'!E62 -> 7597 | I8: ='Бенчмарк'!F62 -> 2521 | J8: ='Бенчмарк'!G62 -> 3 | K8: ='Бенчмарк'!H62 -> 1124000
A9: ="D" & ROW(A8) -> D8 | B9: ='Бенчмарк'!B63 -> устройство 8 (Laptop) x86-64 | C9: ='Бенчмарк'!C63 -> Intel Core Ultra 7 x86-64 | D9: x86-64 | E9: 24 | F9: ='Бенчмарк'!D63 -> 32 | G9: DDR4 | H9: ='Бенчмарк'!E63 -> 1780 | I9: ='Бенчмарк'!F63 -> 553 | J9: ='Бенчмарк'!G63 -> 3.2 | K9: ='Бенчмарк'!H63 -> 348600
A10: ="D" & ROW(A9) -> D9 | B10: ='Бенчмарк'!B64 -> устройство 9 (Desktop) x86-64 | C10: ='Бенчмарк'!C64 -> Intel(R) Core(TM) i5-9400 CPU @ 2,90 GHz x86-64 | D10: x86-64 | E10: 9 | F10: ='Бенчмарк'!D64 -> 8 | G10: DIMM | H10: ='Бенчмарк'!E64 -> 11307 | I10: ='Бенчмарк'!F64 -> 1464 | J10: ='Бенчмарк'!G64 -> 7.7 | K10: ='Бенчмарк'!H64 -> 12221800
B11: ='Бенчмарк'!B65
B12: ='Бенчмарк'!B66
B16: КОРРЕЛЯЦИИ
B17: L3 Кэш vs Ускорение | C17: =CORREL(E2:E10, J2:J10) -> -0.13149585 | D17: Слабая отрицательная связь. Это означает, что алгоритм (индекс) выигрывает везде, но на процессорах с огромным кэшем его относительное преимущество чуть-чуть «подъедается» сверхбыстрым линейным поиском. | G17: Среднее ускорение (арифм.) | H17: =AVERAGE(J2:J10) -> 4.1222222
B18: L3 Кэш vs Линейный поиск | C18: =CORREL(E2:E10, H2:H10) -> -0.55181534 | D18: Это умеренная отрицательная корреляция. Чем больше L3 кэш, тем меньше времени занимает линейный поиск. Это подтверждает гипотезу: аппаратный prefetcher процессора эффективно использует кэш для «проглатывания» последовательных данных. | G18: Среднее ускорение (геом.) | H18: =GEOMEAN(J2:J10) -> 3.9053109
B19: ОЗУ vs Ускорение | C19: =CORREL(F2:F10, J2:J10) -> -0.38489297 | D19: Отрицательная корреляция между объемом ОЗУ и коэффициентом ускорения ($r = -0,38$) объясняется увеличением пропускной способности подсистемы памяти на современных конфигурациях. Высокоскоростная память (DDR4/DDR5) частично нивелирует задержки, возникающие при последовательном сканировании данных (линейный поиск), что приводит к некоторому снижению относительного превосходства индексного поиска по сравнению с системами, оснащенными медленной памятью (DDR3) | G19: Медиана ускорения | H19: =MEDIAN(J2:J10) -> 3.4
B20: ОЗУ vs Линейный поиск | C20: =CORREL(F2:F10, H2:H10) -> -0.72032983 | D20: Сильная отрицательная корреляция. На системах с большим объемом и скоростью ОЗУ (DDR4/DDR5) линейный поиск ускоряется значительнее всего. | G20: Станд. отклонение ускорения | H20: =_xlfn.STDEV.P(J2:J10) -> 1.4808239
B25: Среднее ускорение x86-64 | G25: Коэффициент вариации
B26: Среднее ускорение x86-64 | C26: =POWER(J2*J3*J4*J5*J6*J9*J10,1/7) -> 4.2979166 | F26: Интерпретация: Если CV > 33%, совокупность считается неоднородной. Это научно доказывает тезис: «Алгоритм ведет себя существенно по-разному на разных архитектурах». | G26: =(H20/H17)*100% -> 0.35922952
B27: Среднее ускорение ARM | C27: =POWER(J7*J8,1/2) -> 2.792848
B28: x86 vs ARM по ускорению | C28: =C26/C27 -> 1.538901 | D28: Алгоритм индексной фильтрации на архитектуре x86-64 демонстрирует в среднем на 45% более высокую эффективность (относительно линейного поиска), чем на архитектуре ARM. | F28: Экспериментальные данные подтверждают превосходство предложенного алгоритма над линейным поиском на всех типах устройств. Однако выявлена отрицательная корреляция между объемом L3-кэша и кратностью ускорения ($r = -0.13$). Это объясняется тем, что современные высокопроизводительные процессоры с большими объемами кэш-памяти эффективнее оптимизируют последовательное чтение (линейный поиск), что незначительно сокращает относительный разрыв в производительности по сравнению с системами, обладающими малым объемом кэш-памяти
B29: Разрыв в эффективности | C29: =(C28-1)*100 -> 53.890102 | D29: математически доказал, что архитектурные особенности x86 (объем кэша, работа с памятью) позволяют алгоритму раскрыться на 45% эффективнее, чем на мобильных платформах
B36: на системах с L3 > 16 МБ наблюдается «сближение» результатов из-за аппаратной оптимизации линейного чтения.

Sheet Диаграммы
